Workbook

Sheet Read Me
B2: South African National Elections 2024 — Probability & Cross-Tabulation
B3: Excel-based probability concepts project | Portfolio piece
B5: Contents
B6: • Data | C6: Raw, tidy dataset — one row per Province x Party with real vote counts.
B7: • Cross-Tab | C7: Two-way contingency table (Province x Party) built with SUMIFS formulas.
B8: • Probabilities | C8: Empirical, marginal, joint, and conditional probability calculations, all formula-driven.
B10: Data source
B11: Electoral Commission of South Africa (IEC) — official 2024 Provincial Legislature
B12: election results (provincial ballot), 29 May 2024. Compiled via Wikipedia:
B13: '2024 South African provincial elections'. Figures are the real, official vote
B14: counts for the top 5 parties by national seat count in each of the 9 provinces.
B16: How to use
B17: 1. Start on 'Data' to see the tidy source table (Province, Party, Votes).
B18: 2. 'Cross-Tab' pivots that data into a contingency table using SUMIFS — the
B19: classic first step of a probability/statistics analysis in Excel.
B20: 3. 'Probabilities' derives empirical, marginal, joint and conditional
B21: probabilities directly from the cross-tab, all as live formulas.

Sheet Data
A1: province | B1: party | C1: votes
A2: Eastern Cape | B2: ANC | C2: 1114294
A3: Eastern Cape | B3: DA | C3: 267007
A4: Eastern Cape | B4: EFF | C4: 181855
A5: Eastern Cape | B5: MK | C5: 25904
A6: Eastern Cape | B6: IFP | C6: 1343
A7: Free State | B7: ANC | C7: 429241
A8: Free State | B8: DA | C8: 181062
A9: Free State | B9: EFF | C9: 111850
A10: Free State | B10: MK | C10: 15985
A11: Free State | B11: IFP | C11: 1537
A12: Gauteng | B12: ANC | C12: 1367248
A13: Gauteng | B13: DA | C13: 1079229
... A46: Western Cape | B46: IFP | C46: 824
A48: Source: Electoral Commission of South Africa, official 2024 provincial ballot results (via Wikipedia).

Sheet Cross-Tab
A1: Province | B1: ANC | C1: DA | D1: EFF | E1: MK | F1: IFP | G1: Row Total
A2: Eastern Cape | B2: =SUMIFS(Data!$C$2:$C$46,Data!$A$2:$A$46,$A2,Data!$B$2:$B$46,B$1) -> 1114294 | C2: =SUMIFS(Data!$C$2:$C$46,Data!$A$2:$A$46,$A2,Data!$B$2:$B$46,C$1) -> 267007 | D2: =SUMIFS(Data!$C$2:$C$46,Data!$A$2:$A$46,$A2,Data!$B$2:$B$46,D$1) -> 181855 | E2: =SUMIFS(Data!$C$2:$C$46,Data!$A$2:$A$46,$A2,Data!$B$2:$B$46,E$1) -> 25904 | F2: =SUMIFS(Data!$C$2:$C$46,Data!$A$2:$A$46,$A2,Data!$B$2:$B$46,F$1) -> 1343 | G2: =SUM(B2:F2) -> 1590403
A3: Free State | B3: =SUMIFS(Data!$C$2:$C$46,Data!$A$2:$A$46,$A3,Data!$B$2:$B$46,B$1) -> 429241 | C3: =SUMIFS(Data!$C$2:$C$46,Data!$A$2:$A$46,$A3,Data!$B$2:$B$46,C$1) -> 181062 | D3: =SUMIFS(Data!$C$2:$C$46,Data!$A$2:$A$46,$A3,Data!$B$2:$B$46,D$1) -> 111850 | E3: =SUMIFS(Data!$C$2:$C$46,Data!$A$2:$A$46,$A3,Data!$B$2:$B$46,E$1) -> 15985 | F3: =SUMIFS(Data!$C$2:$C$46,Data!$A$2:$A$46,$A3,Data!$B$2:$B$46,F$1) -> 1537 | G3: =SUM(B3:F3) -> 739675
A4: Gauteng | B4: =SUMIFS(Data!$C$2:$C$46,Data!$A$2:$A$46,$A4,Data!$B$2:$B$46,B$1) -> 1367248 | C4: =SUMIFS(Data!$C$2:$C$46,Data!$A$2:$A$46,$A4,Data!$B$2:$B$46,C$1) -> 1079229 | D4: =SUMIFS(Data!$C$2:$C$46,Data!$A$2:$A$46,$A4,Data!$B$2:$B$46,D$1) -> 508390 | E4: =SUMIFS(Data!$C$2:$C$46,Data!$A$2:$A$46,$A4,Data!$B$2:$B$46,E$1) -> 384968 | F4: =SUMIFS(Data!$C$2:$C$46,Data!$A$2:$A$46,$A4,Data!$B$2:$B$46,F$1) -> 34250 | G4: =SUM(B4:F4) -> 3374085
A5: KwaZulu-Natal | B5: =SUMIFS(Data!$C$2:$C$46,Data!$A$2:$A$46,$A5,Data!$B$2:$B$46,B$1) -> 595958 | C5: =SUMIFS(Data!$C$2:$C$46,Data!$A$2:$A$46,$A5,Data!$B$2:$B$46,C$1) -> 468515 | D5: =SUMIFS(Data!$C$2:$C$46,Data!$A$2:$A$46,$A5,Data!$B$2:$B$46,D$1) -> 79211 | E5: =SUMIFS(Data!$C$2:$C$46,Data!$A$2:$A$46,$A5,Data!$B$2:$B$46,E$1) -> 1590813 | F5: =SUMIFS(Data!$C$2:$C$46,Data!$A$2:$A$46,$A5,Data!$B$2:$B$46,F$1) -> 633771 | G5: =SUM(B5:F5) -> 3368268
A6: Limpopo | B6: =SUMIFS(Data!$C$2:$C$46,Data!$A$2:$A$46,$A6,Data!$B$2:$B$46,B$1) -> 1037627 | C6: =SUMIFS(Data!$C$2:$C$46,Data!$A$2:$A$46,$A6,Data!$B$2:$B$46,C$1) -> 84388 | D6: =SUMIFS(Data!$C$2:$C$46,Data!$A$2:$A$46,$A6,Data!$B$2:$B$46,D$1) -> 199900 | E6: =SUMIFS(Data!$C$2:$C$46,Data!$A$2:$A$46,$A6,Data!$B$2:$B$46,E$1) -> 12027 | F6: =SUMIFS(Data!$C$2:$C$46,Data!$A$2:$A$46,$A6,Data!$B$2:$B$46,F$1) -> 890 | G6: =SUM(B6:F6) -> 1334832
A7: Mpumalanga | B7: =SUMIFS(Data!$C$2:$C$46,Data!$A$2:$A$46,$A7,Data!$B$2:$B$46,B$1) -> 584609 | C7: =SUMIFS(Data!$C$2:$C$46,Data!$A$2:$A$46,$A7,Data!$B$2:$B$46,C$1) -> 137408 | D7: =SUMIFS(Data!$C$2:$C$46,Data!$A$2:$A$46,$A7,Data!$B$2:$B$46,D$1) -> 158511 | E7: =SUMIFS(Data!$C$2:$C$46,Data!$A$2:$A$46,$A7,Data!$B$2:$B$46,E$1) -> 193995 | F7: =SUMIFS(Data!$C$2:$C$46,Data!$A$2:$A$46,$A7,Data!$B$2:$B$46,F$1) -> 5352 | G7: =SUM(B7:F7) -> 1079875
A8: North West | B8: =SUMIFS(Data!$C$2:$C$46,Data!$A$2:$A$46,$A8,Data!$B$2:$B$46,B$1) -> 510994 | C8: =SUMIFS(Data!$C$2:$C$46,Data!$A$2:$A$46,$A8,Data!$B$2:$B$46,C$1) -> 117168 | D8: =SUMIFS(Data!$C$2:$C$46,Data!$A$2:$A$46,$A8,Data!$B$2:$B$46,D$1) -> 153743 | E8: =SUMIFS(Data!$C$2:$C$46,Data!$A$2:$A$46,$A8,Data!$B$2:$B$46,E$1) -> 18198 | F8: =SUMIFS(Data!$C$2:$C$46,Data!$A$2:$A$46,$A8,Data!$B$2:$B$46,F$1) -> 1335 | G8: =SUM(B8:F8) -> 801438
A9: Northern Cape | B9: =SUMIFS(Data!$C$2:$C$46,Data!$A$2:$A$46,$A9,Data!$B$2:$B$46,B$1) -> 195267 | C9: =SUMIFS(Data!$C$2:$C$46,Data!$A$2:$A$46,$A9,Data!$B$2:$B$46,C$1) -> 83848 | D9: =SUMIFS(Data!$C$2:$C$46,Data!$A$2:$A$46,$A9,Data!$B$2:$B$46,D$1) -> 52433 | E9: =SUMIFS(Data!$C$2:$C$46,Data!$A$2:$A$46,$A9,Data!$B$2:$B$46,E$1) -> 3111 | F9: =SUMIFS(Data!$C$2:$C$46,Data!$A$2:$A$46,$A9,Data!$B$2:$B$46,F$1) -> 303 | G9: =SUM(B9:F9) -> 334962
A10: Western Cape | B10: =SUMIFS(Data!$C$2:$C$46,Data!$A$2:$A$46,$A10,Data!$B$2:$B$46,B$1) -> 384853 | C10: =SUMIFS(Data!$C$2:$C$46,Data!$A$2:$A$46,$A10,Data!$B$2:$B$46,C$1) -> 1088423 | D10: =SUMIFS(Data!$C$2:$C$46,Data!$A$2:$A$46,$A10,Data!$B$2:$B$46,D$1) -> 104354 | E10: =SUMIFS(Data!$C$2:$C$46,Data!$A$2:$A$46,$A10,Data!$B$2:$B$46,E$1) -> 11263 | F10: =SUMIFS(Data!$C$2:$C$46,Data!$A$2:$A$46,$A10,Data!$B$2:$B$46,F$1) -> 824 | G10: =SUM(B10:F10) -> 1589717
A11: Column Total | B11: =SUM(B2:B10) -> 6220091 | C11: =SUM(C2:C10) -> 3507048 | D11: =SUM(D2:D10) -> 1550247 | E11: =SUM(E2:E10) -> 2256264 | F11: =SUM(F2:F10) -> 679605 | G11: =SUM(G2:G10) -> 14213255
A13: Grand total votes (all provinces, top 5 parties): ='Cross-Tab'!G11

Sheet Probabilities
B2: Probability Concepts — derived from the Cross-Tab
B3: All values below are LIVE FORMULAS referencing the 'Cross-Tab' sheet.
B5: 1) Empirical / Marginal Probability — P(Party)
B6: Party | C6: Votes | D6: P(Party) = Votes / Grand Total
B7: ANC | C7: ='Cross-Tab'!B11 -> 6220091 | D7: =C7/$C$13 -> 0.43762608
B8: DA | C8: ='Cross-Tab'!C11 -> 3507048 | D8: =C8/$C$13 -> 0.24674489
B9: EFF | C9: ='Cross-Tab'!D11 -> 1550247 | D9: =C9/$C$13 -> 0.10907051
B10: MK | C10: ='Cross-Tab'!E11 -> 2256264 | D10: =C10/$C$13 -> 0.15874365
B11: IFP | C11: ='Cross-Tab'!F11 -> 679605 | D11: =C11/$C$13 -> 0.047814874
B13: Grand Total | C13: =SUM(C7:C11) -> 14213255 | D13: =SUM(D7:D11) -> 1
B15: Note: this is the empirical probability of a randomly selected ballot (among the top 5
B16: parties, across all 9 provinces) belonging to a given party — i.e. its overall vote share.
B18: 2) Marginal Probability — P(Province)
B19: Province | C19: Votes | D19: P(Province) = Votes / Grand Total
B20: Eastern Cape | C20: ='Cross-Tab'!G2 -> 1590403 | D20: =C20/$C$30 -> 0.11189576
B21: Free State | C21: ='Cross-Tab'!G3 -> 739675 | D21: =C21/$C$30 -> 0.052041211
B22: Gauteng | C22: ='Cross-Tab'!G4 -> 3374085 | D22: =C22/$C$30 -> 0.23739003
B23: KwaZulu-Natal | C23: ='Cross-Tab'!G5 -> 3368268 | D23: =C23/$C$30 -> 0.23698076
B24: Limpopo | C24: ='Cross-Tab'!G6 -> 1334832 | D24: =C24/$C$30 -> 0.093914589
B25: Mpumalanga | C25: ='Cross-Tab'!G7 -> 1079875 | D25: =C25/$C$30 -> 0.075976615
B26: North West | C26: ='Cross-Tab'!G8 -> 801438 | D26: =C26/$C$30 -> 0.056386662
B27: Northern Cape | C27: ='Cross-Tab'!G9 -> 334962 | D27: =C27/$C$30 -> 0.023566875
B28: Western Cape | C28: ='Cross-Tab'!G10 -> 1589717 | D28: =C28/$C$30 -> 0.1118475
B30: Grand Total | C30: =SUM(C20:C28) -> 14213255 | D30: =SUM(D20:D28) -> 1
B32: 3) Joint Probability — P(Province AND Party) = cell votes / Grand Total
B33: Province | C33: ANC | D33: DA | E33: EFF | F33: MK | G33: IFP
B34: Eastern Cape | C34: ='Cross-Tab'!B2/'Cross-Tab'!G11 -> 0.078398228 | D34: ='Cross-Tab'!C2/'Cross-Tab'!G11 -> 0.018785774 | E34: ='Cross-Tab'!D2/'Cross-Tab'!G11 -> 0.012794747 | F34: ='Cross-Tab'!E2/'Cross-Tab'!G11 -> 0.0018225241 | G34: ='Cross-Tab'!F2/'Cross-Tab'!G11 -> 9.4489264e-05
B35: Free State | C35: ='Cross-Tab'!B3/'Cross-Tab'!G11 -> 0.030200049 | D35: ='Cross-Tab'!C3/'Cross-Tab'!G11 -> 0.012738954 | E35: ='Cross-Tab'!D3/'Cross-Tab'!G11 -> 0.0078694149 | F35: ='Cross-Tab'!E3/'Cross-Tab'!G11 -> 0.0011246544 | G35: ='Cross-Tab'!F3/'Cross-Tab'!G11 -> 0.00010813849
B36: Gauteng | C36: ='Cross-Tab'!B4/'Cross-Tab'!G11 -> 0.096195277 | D36: ='Cross-Tab'!C4/'Cross-Tab'!G11 -> 0.075931164 | E36: ='Cross-Tab'!D4/'Cross-Tab'!G11 -> 0.035768724 | F36: ='Cross-Tab'!E4/'Cross-Tab'!G11 -> 0.02708514 | G36: ='Cross-Tab'!F4/'Cross-Tab'!G11 -> 0.0024097225
B37: KwaZulu-Natal | C37: ='Cross-Tab'!B5/'Cross-Tab'!G11 -> 0.041929734 | D37: ='Cross-Tab'!C5/'Cross-Tab'!G11 -> 0.032963245 | E37: ='Cross-Tab'!D5/'Cross-Tab'!G11 -> 0.0055730373 | F37: ='Cross-Tab'!E5/'Cross-Tab'!G11 -> 0.11192461 | G37: ='Cross-Tab'!F5/'Cross-Tab'!G11 -> 0.044590138
B38: Limpopo | C38: ='Cross-Tab'!B6/'Cross-Tab'!G11 -> 0.073004178 | D38: ='Cross-Tab'!C6/'Cross-Tab'!G11 -> 0.0059372747 | E38: ='Cross-Tab'!D6/'Cross-Tab'!G11 -> 0.014064336 | F38: ='Cross-Tab'!E6/'Cross-Tab'!G11 -> 0.00084618196 | G38: ='Cross-Tab'!F6/'Cross-Tab'!G11 -> 6.2617606e-05
B39: Mpumalanga | C39: ='Cross-Tab'!B7/'Cross-Tab'!G11 -> 0.041131254 | D39: ='Cross-Tab'!C7/'Cross-Tab'!G11 -> 0.0096675955 | E39: ='Cross-Tab'!D7/'Cross-Tab'!G11 -> 0.011152336 | F39: ='Cross-Tab'!E7/'Cross-Tab'!G11 -> 0.013648879 | G39: ='Cross-Tab'!F7/'Cross-Tab'!G11 -> 0.00037654992
B40: North West | C40: ='Cross-Tab'!B8/'Cross-Tab'!G11 -> 0.035951934 | D40: ='Cross-Tab'!C8/'Cross-Tab'!G11 -> 0.0082435726 | E40: ='Cross-Tab'!D8/'Cross-Tab'!G11 -> 0.010816875 | F40: ='Cross-Tab'!E8/'Cross-Tab'!G11 -> 0.0012803541 | G40: ='Cross-Tab'!F8/'Cross-Tab'!G11 -> 9.3926409e-05
B41: Northern Cape | C41: ='Cross-Tab'!B9/'Cross-Tab'!G11 -> 0.013738373 | D41: ='Cross-Tab'!C9/'Cross-Tab'!G11 -> 0.005899282 | E41: ='Cross-Tab'!D9/'Cross-Tab'!G11 -> 0.0036890213 | F41: ='Cross-Tab'!E9/'Cross-Tab'!G11 -> 0.00021888019 | G41: ='Cross-Tab'!F9/'Cross-Tab'!G11 -> 2.1318129e-05
B42: Western Cape | C42: ='Cross-Tab'!B10/'Cross-Tab'!G11 -> 0.027077049 | D42: ='Cross-Tab'!C10/'Cross-Tab'!G11 -> 0.076578025 | E42: ='Cross-Tab'!D10/'Cross-Tab'!G11 -> 0.0073420198 | F42: ='Cross-Tab'!E10/'Cross-Tab'!G11 -> 0.00079242932 | G42: ='Cross-Tab'!F10/'Cross-Tab'!G11 -> 5.7974053e-05
B44: Sanity check — all joint probabilities sum to 100%: | H44: =SUM(C34:G42) -> 1
B47: 4) Conditional Probability — P(Party | Province) = cell votes / Province Row Total
B48: Province | C48: ANC | D48: DA | E48: EFF | F48: MK | G48: IFP
B49: Eastern Cape | C49: ='Cross-Tab'!B2/'Cross-Tab'!G2 -> 0.70063625 | D49: ='Cross-Tab'!C2/'Cross-Tab'!G2 -> 0.16788638 | E49: ='Cross-Tab'!D2/'Cross-Tab'!G2 -> 0.11434523 | F49: ='Cross-Tab'!E2/'Cross-Tab'!G2 -> 0.016287696 | G49: ='Cross-Tab'!F2/'Cross-Tab'!G2 -> 0.00084444006
B50: Free State | C50: ='Cross-Tab'!B3/'Cross-Tab'!G3 -> 0.58031027 | D50: ='Cross-Tab'!C3/'Cross-Tab'!G3 -> 0.24478589 | E50: ='Cross-Tab'!D3/'Cross-Tab'!G3 -> 0.15121506 | F50: ='Cross-Tab'!E3/'Cross-Tab'!G3 -> 0.021610843 | G50: ='Cross-Tab'!F3/'Cross-Tab'!G3 -> 0.0020779396
...
